<sdf version='1.6'>
  <world name='default'>
    <gui fullscreen='0'>
      <plugin name='video_widget' filename='libgazebo_video_stream_widget.so'/>
      <camera name='user_camera'>
        <pose frame=''>3.4449 -8.95044 49.6674 0 1.47964 -0.083808</pose>
        <view_controller>orbit</view_controller>
        <projection_type>perspective</projection_type>
      </camera>
    </gui>
    <light name='sun' type='directional'>
      <cast_shadows>1</cast_shadows>
      <pose frame=''>0 0 10 0 -0 0</pose>
      <diffuse>0.8 0.8 0.8 1</diffuse>
      <specular>0.1 0.1 0.1 1</specular>
      <attenuation>
        <range>1000</range>
        <constant>0.9</constant>
        <linear>0.01</linear>
        <quadratic>0.001</quadratic>
      </attenuation>
      <direction>-0.5 0.5 -1</direction>
    </light>
    <scene>
      <ambient>0.01 0.01 0.01 1</ambient>
      <sky>
        <clouds>
          <speed>12</speed>
        </clouds>
      </sky>
      <shadows>1</shadows>
      <background>0.7 0.7 0.7 1</background>
    </scene>
    <light name='sun1' type='directional'>
      <pose frame=''>50 0 150 0 -0 0</pose>
      <diffuse>1 1 1 1</diffuse>
      <specular>0.1 0.1 0.1 1</specular>
      <direction>0.3 0.3 -1</direction>
      <cast_shadows>0</cast_shadows>
    </light>
    <light name='sun_diffuse' type='directional'>
      <pose frame=''>-50 0 -150 0 -0 0</pose>
      <diffuse>0.6 0.6 0.6 1</diffuse>
      <specular>0 0 0 1</specular>
      <direction>-0.3 -0.3 -1</direction>
      <cast_shadows>0</cast_shadows>
    </light>
    <light name='sun2' type='directional'>
      <pose frame=''>0 50 0 0 -0 0</pose>
      <diffuse>1 1 1 1</diffuse>
      <specular>0.1 0.1 0.1 1</specular>
      <direction>-0.3 0.3 -1</direction>
      <cast_shadows>0</cast_shadows>
    </light>
    <light name='sun3' type='directional'>
      <pose frame=''>0 -50 0 0 -0 0</pose>
      <diffuse>1 1 1 1</diffuse>
      <specular>0.1 0.1 0.1 1</specular>
      <direction>0.3 -0.3 1</direction>
      <cast_shadows>0</cast_shadows>
    </light>
    <model name='world_ned'>
      <pose frame=''>0 0 0 0 -0 0</pose>
      <static>1</static>
      <link name='world_ned'>
        <gravity>0</gravity>
        <pose frame=''>0 0 0 -3.14159 -0 1.5708</pose>
        <visual name='N_visual'>
          <pose frame=''>0.25 0 0 1.5708 -0 1.5708</pose>
          <geometry>
            <cylinder>
              <radius>0.01</radius>
              <length>0.5</length>
            </cylinder>
          </geometry>
          <material>
            <script>
              <uri>file://media/materials/scripts/gazebo.material</uri>
              <name>Gazebo/Red</name>
            </script>
          </material>
        </visual>
        <visual name='E_visual'>
          <pose frame=''>0 0.25 0 1.5708 -0 0</pose>
          <geometry>
            <cylinder>
              <radius>0.01</radius>
              <length>0.5</length>
            </cylinder>
          </geometry>
          <material>
            <script>
              <uri>file://media/materials/scripts/gazebo.material</uri>
              <name>Gazebo/Green</name>
            </script>
          </material>
        </visual>
        <visual name='D_visual'>
          <pose frame=''>0 0 0.25 0 -0 0</pose>
          <geometry>
            <cylinder>
              <radius>0.01</radius>
              <length>0.5</length>
            </cylinder>
          </geometry>
          <material>
            <script>
              <uri>file://media/materials/scripts/gazebo.material</uri>
              <name>Gazebo/Blue</name>
            </script>
          </material>
        </visual>
        <self_collide>0</self_collide>
        <kinematic>0</kinematic>
      </link>
    </model>
    <physics name='default_physics' default='0' type='ode'>
      <ode>
        <solver>
          <type>quick</type>
          <iters>50</iters>
          <sor>1</sor>
          <use_dynamic_moi_rescaling>0</use_dynamic_moi_rescaling>
        </solver>
        <constraints>
          <cfm>0</cfm>
          <erp>0.2</erp>
          <contact_max_correcting_vel>100</contact_max_correcting_vel>
          <contact_surface_layer>0.001</contact_surface_layer>
        </constraints>
      </ode>
      <max_step_size>0.004</max_step_size>
      <real_time_factor>1</real_time_factor>
      <real_time_update_rate>250</real_time_update_rate>
    </physics>
    <gravity>0 0 -9.8066</gravity>
    <magnetic_field>6e-06 2.3e-05 -4.2e-05</magnetic_field>
    <atmosphere type='adiabatic'/>
    <spherical_coordinates>
      <surface_model>EARTH_WGS84</surface_model>
      <latitude_deg>0</latitude_deg>
      <longitude_deg>0</longitude_deg>
      <elevation>0</elevation>
      <heading_deg>0</heading_deg>
    </spherical_coordinates>
    <model name='typhoon_h480'>
      <pose frame=''>1.01 0.98 0.83 0 -0 0</pose>
      <link name='base_link'>
        <pose frame=''>0 0 0 0 -0 0</pose>
        <inertial>
          <pose frame=''>0.001005 0 -0.009004 0 -0 0</pose>
          <mass>2.02</mass>
          <inertia>
            <ixx>0.011</ixx>
            <ixy>0</ixy>
            <ixz>0</ixz>
            <iyy>0.015</iyy>
            <iyz>0</iyz>
            <izz>0.021</izz>
          </inertia>
        </inertial>
        <collision name='base_link_collision'>
          <pose frame=''>0 0 0 0 -0 0</pose>
          <geometry>
            <box>
              <size>0.67 0.67 0.15</size>
            </box>
          </geometry>
          <surface>
            <contact>
              <ode>
                <min_depth>0.001</min_depth>
                <max_vel>0</max_vel>
              </ode>
            </contact>
            <friction>
              <ode/>
              <torsional>
                <ode/>
              </torsional>
            </friction>
            <bounce/>
          </surface>
          <max_contacts>10</max_contacts>
        </collision>
        <visual name='base_link_visual'>
          <pose frame=''>0 0 0 0 -0 3.14159</pose>
          <geometry>
            <mesh>
              <scale>1 1 1</scale>
              <uri>model://typhoon_h480/meshes/main_body_remeshed_v3.stl</uri>
            </mesh>
          </geometry>
          <material>
            <script>
              <name>Gazebo/DarkGrey</name>
              <uri>file://media/materials/scripts/gazebo.material</uri>
            </script>
          </material>
        </visual>
        <gravity>1</gravity>
        <velocity_decay/>
        <self_collide>0</self_collide>
        <kinematic>0</kinematic>
      </link>
      <link name='cgo3_mount_link'>
        <inertial>
          <pose frame=''>-0.041 0 -0.162 0 -0 0</pose>
          <mass>0.1</mass>
          <inertia>
            <ixx>0.001</ixx>
            <ixy>0</ixy>
            <ixz>0</ixz>
            <iyy>0.001</iyy>
            <iyz>0</iyz>
            <izz>0.001</izz>
          </inertia>
        </inertial>
        <visual name='cgo3_mount_visual'>
          <pose frame=''>0 0 0 0 -0 0</pose>
          <geometry>
            <mesh>
              <scale>1 1 1</scale>
              <uri>model://typhoon_h480/meshes/cgo3_mount_remeshed_v1.stl</uri>
            </mesh>
          </geometry>
          <material>
            <script>
              <name>Gazebo/DarkGrey</name>
              <uri>file://media/materials/scripts/gazebo.material</uri>
            </script>
          </material>
        </visual>
        <self_collide>0</self_collide>
        <kinematic>0</kinematic>
        <gravity>1</gravity>
      </link>
      <joint name='cgo3_mount_joint' type='revolute'>
        <child>cgo3_mount_link</child>
        <parent>base_link</parent>
        <pose frame=''>0 0 0 0 -0 0</pose>
        <axis>
          <xyz>0 0 1</xyz>
          <limit>
            <lower>0</lower>
            <upper>0</upper>
            <effort>100</effort>
            <velocity>-1</velocity>
          </limit>
          <dynamics>
            <damping>1</damping>
            <spring_reference>0</spring_reference>
            <spring_stiffness>0</spring_stiffness>
          </dynamics>
          <use_parent_model_frame>1</use_parent_model_frame>
        </axis>
        <physics>
          <ode>
            <implicit_spring_damper>1</implicit_spring_damper>
            <limit>
              <cfm>0</cfm>
              <erp>0.2</erp>
            </limit>
          </ode>
        </physics>
      </joint>
      <link name='cgo3_vertical_arm_link'>
        <inertial>
          <pose frame=''>-0.041 0 -0.162 0 -0 0</pose>
          <mass>0.1</mass>
          <inertia>
            <ixx>0.001</ixx>
            <ixy>0</ixy>
            <ixz>0</ixz>
            <iyy>0.001</iyy>
            <iyz>0</iyz>
            <izz>0.001</izz>
          </inertia>
        </inertial>
        <visual name='cgo3_vertical_arm_visual'>
          <pose frame=''>-0.051 0 0 0 -0 3.14159</pose>
          <geometry>
            <mesh>
              <scale>1 1 1</scale>
              <uri>model://typhoon_h480/meshes/cgo3_vertical_arm_remeshed_v1.stl</uri>
            </mesh>
          </geometry>
          <material>
            <script>
              <name>Gazebo/DarkGrey</name>
              <uri>file://media/materials/scripts/gazebo.material</uri>
            </script>
          </material>
        </visual>
        <self_collide>0</self_collide>
        <kinematic>0</kinematic>
        <gravity>1</gravity>
      </link>
      <joint name='cgo3_vertical_arm_joint' type='revolute'>
        <child>cgo3_vertical_arm_link</child>
        <parent>cgo3_mount_link</parent>
        <pose frame=''>-0.026 0 -0.1 0 -0 0</pose>
        <axis>
          <xyz>0 0 1</xyz>
          <limit>
            <lower>-1e+16</lower>
            <upper>1e+16</upper>
            <effort>100</effort>
            <velocity>-1</velocity>
          </limit>
          <dynamics>
            <damping>0.1</damping>
            <spring_reference>0</spring_reference>
            <spring_stiffness>0</spring_stiffness>
          </dynamics>
          <use_parent_model_frame>1</use_parent_model_frame>
        </axis>
        <physics>
          <ode>
            <implicit_spring_damper>1</implicit_spring_damper>
            <limit>
              <cfm>0.1</cfm>
              <erp>0.2</erp>
            </limit>
          </ode>
        </physics>
      </joint>
      <link name='cgo3_horizontal_arm_link'>
        <inertial>
          <pose frame=''>-0.041 0 -0.081 0 -0 0</pose>
          <mass>0.1</mass>
          <inertia>
            <ixx>0.001</ixx>
            <ixy>0</ixy>
            <ixz>0</ixz>
            <iyy>0.001</iyy>
            <iyz>0</iyz>
            <izz>0.001</izz>
          </inertia>
        </inertial>
        <visual name='cgo3_horizontal_arm_visual'>
          <pose frame=''>-0.05 0 0 0 -0 3.14159</pose>
          <geometry>
            <mesh>
              <scale>1 1 1</scale>
              <uri>model://typhoon_h480/meshes/cgo3_horizontal_arm_remeshed_v1.stl</uri>
            </mesh>
          </geometry>
          <material>
            <script>
              <name>Gazebo/DarkGrey</name>
              <uri>file://media/materials/scripts/gazebo.material</uri>
            </script>
          </material>
        </visual>
        <self_collide>0</self_collide>
        <kinematic>0</kinematic>
        <gravity>1</gravity>
      </link>
      <joint name='cgo3_horizontal_arm_joint' type='revolute'>
        <child>cgo3_horizontal_arm_link</child>
        <parent>cgo3_vertical_arm_link</parent>
        <pose frame=''>-0.07 0 -0.162 0 -0 0</pose>
        <axis>
          <xyz>-1 0 0</xyz>
          <limit>
            <lower>-0.785398</lower>
            <upper>0.785398</upper>
            <effort>100</effort>
            <velocity>-1</velocity>
          </limit>
          <dynamics>
            <damping>0.1</damping>
            <spring_reference>0</spring_reference>
            <spring_stiffness>0</spring_stiffness>
          </dynamics>
          <use_parent_model_frame>1</use_parent_model_frame>
        </axis>
        <physics>
          <ode>
            <implicit_spring_damper>1</implicit_spring_damper>
            <limit>
              <cfm>0.1</cfm>
              <erp>0.2</erp>
            </limit>
          </ode>
        </physics>
      </joint>
      <link name='cgo3_camera_link'>
        <inertial>
          <pose frame=''>-0.041 0 -0.162 0 -0 0</pose>
          <mass>0.1</mass>
          <inertia>
            <ixx>0.001</ixx>
            <ixy>0</ixy>
            <ixz>0</ixz>
            <iyy>0.001</iyy>
            <iyz>0</iyz>
            <izz>0.001</izz>
          </inertia>
        </inertial>
        <collision name='cgo3_camera_collision'>
          <pose frame=''>-0.041 0 -0.162 0 -0 0</pose>
          <geometry>
            <sphere>
              <radius>0.035</radius>
            </sphere>
          </geometry>
          <surface>
            <friction>
              <ode>
                <mu>1</mu>
                <mu2>1</mu2>
              </ode>
              <torsional>
                <ode/>
              </torsional>
            </friction>
            <contact>
              <ode>
                <kp>1e+08</kp>
                <kd>1</kd>
                <max_vel>0.01</max_vel>
                <min_depth>0.001</min_depth>
              </ode>
            </contact>
            <bounce/>
          </surface>
          <max_contacts>10</max_contacts>
        </collision>
        <visual name='cgo3_camera_visual'>
          <pose frame=''>-0.05 0 0 0 -0 3.14159</pose>
          <geometry>
            <mesh>
              <scale>1 1 1</scale>
              <uri>model://typhoon_h480/meshes/cgo3_camera_remeshed_v1.stl</uri>
            </mesh>
          </geometry>
          <material>
            <script>
              <name>Gazebo/DarkGrey</name>
              <uri>file://media/materials/scripts/gazebo.material</uri>
            </script>
          </material>
        </visual>
        <sensor name='camera_imu' type='imu'>
          <always_on>1</always_on>
        </sensor>
        <sensor name='camera' type='camera'>
          <pose frame=''>0 0 -0.162 0 -0 0</pose>
          <camera name='__default__'>
            <horizontal_fov>2</horizontal_fov>
            <image>
              <format>R8G8B8</format>
              <width>640</width>
              <height>360</height>
            </image>
            <clip>
              <near>0.05</near>
              <far>15000</far>
            </clip>
          </camera>
          <always_on>1</always_on>
          <update_rate>10</update_rate>
          <visualize>1</visualize>
          <plugin name='GstCameraPlugin' filename='libgazebo_gst_camera_plugin.so'>
            <robotNamespace/>
            <udpHost>127.0.0.1</udpHost>
            <udpPort>5600</udpPort>
          </plugin>
          <plugin name='GeotaggedImagesPlugin' filename='libgazebo_geotagged_images_plugin.so'>
            <robotNamespace>typhoon_h480</robotNamespace>
            <interval>1</interval>
            <width>3840</width>
            <height>2160</height>
            <maximum_zoom>8.0</maximum_zoom>
          </plugin>
        </sensor>
        <self_collide>0</self_collide>
        <kinematic>0</kinematic>
        <gravity>1</gravity>
      </link>
      <joint name='cgo3_camera_joint' type='revolute'>
        <child>cgo3_camera_link</child>
        <parent>cgo3_horizontal_arm_link</parent>
        <pose frame=''>-0.01 0.03 -0.162 0 -0 0</pose>
        <axis>
          <xyz>0 -1 0</xyz>
          <limit>
            <lower>-1.05</lower>
            <upper>2.09</upper>
            <effort>100</effort>
            <velocity>-1</velocity>
          </limit>
          <dynamics>
            <damping>0.1</damping>
            <spring_reference>0</spring_reference>
            <spring_stiffness>0</spring_stiffness>
          </dynamics>
          <use_parent_model_frame>1</use_parent_model_frame>
        </axis>
        <physics>
          <ode>
            <implicit_spring_damper>1</implicit_spring_damper>
            <limit>
              <cfm>0.1</cfm>
              <erp>0.2</erp>
            </limit>
          </ode>
        </physics>
      </joint>
      <link name='left_leg'>
        <inertial>
          <pose frame=''>0 -0.14314 -0.207252 0 -0 0</pose>
          <mass>0.1</mass>
          <inertia>
            <ixx>0.001</ixx>
            <ixy>0</ixy>
            <ixz>0</ixz>
            <iyy>0.001</iyy>
            <iyz>0</iyz>
            <izz>0.001</izz>
          </inertia>
        </inertial>
        <collision name='collision'>
          <pose frame=''>-0.005 -0.14314 -0.207252 0 1.56893 0</pose>
          <geometry>
            <cylinder>
              <radius>0.012209</radius>
              <length>0.3</length>
            </cylinder>
          </geometry>
          <surface>
            <friction>
              <ode>
                <mu>1</mu>
                <mu2>1</mu2>
              </ode>
              <torsional>
                <ode/>
              </torsional>
            </friction>
            <contact>
              <ode>
                <kp>1e+08</kp>
                <kd>1</kd>
                <max_vel>0.01</max_vel>
                <min_depth>0.001</min_depth>
              </ode>
            </contact>
            <bounce/>
          </surface>
          <max_contacts>10</max_contacts>
        </collision>
        <collision name='collision_bar'>
          <pose frame=''>0.00052 -0.08503 -0.121187 -0.501318 0 0</pose>
          <geometry>
            <cylinder>
              <radius>0.00914984</radius>
              <length>0.176893</length>
            </cylinder>
          </geometry>
          <surface>
            <friction>
              <ode>
                <mu>1</mu>
                <mu2>1</mu2>
              </ode>
              <torsional>
                <ode/>
              </torsional>
            </friction>
            <contact>
              <ode>
                <kp>1e+08</kp>
                <kd>1</kd>
                <max_vel>0.01</max_vel>
                <min_depth>0.001</min_depth>
              </ode>
            </contact>
            <bounce/>
          </surface>
          <max_contacts>10</max_contacts>
        </collision>
        <visual name='base_link_left_leg'>
          <pose frame=''>0 0 0 0 -0 0</pose>
          <geometry>
            <mesh>
              <scale>1 1 1</scale>
              <uri>model://typhoon_h480/meshes/leg2_remeshed_v3.stl</uri>
            </mesh>
          </geometry>
          <material>
            <script>
              <name>Gazebo/DarkGrey</name>
              <uri>file://media/materials/scripts/gazebo.material</uri>
            </script>
          </material>
        </visual>
        <self_collide>0</self_collide>
        <kinematic>0</kinematic>
        <gravity>1</gravity>
      </link>
      <joint name='left_leg_joint' type='revolute'>
        <child>left_leg</child>
        <parent>base_link</parent>
        <pose frame=''>0.00026 -0.040515 -0.048 0 -0 0</pose>
        <axis>
          <xyz>-1 0 0</xyz>
          <limit>
            <lower>0</lower>
            <upper>1</upper>
            <effort>100</effort>
            <velocity>-1</velocity>
            <stiffness>1e+08</stiffness>
            <dissipation>1</dissipation>
          </limit>
          <dynamics>
            <damping>0.1</damping>
            <spring_reference>0</spring_reference>
            <spring_stiffness>0</spring_stiffness>
          </dynamics>
          <use_parent_model_frame>1</use_parent_model_frame>
        </axis>
        <physics>
          <ode>
            <implicit_spring_damper>1</implicit_spring_damper>
            <limit>
              <cfm>0</cfm>
              <erp>0.2</erp>
            </limit>
          </ode>
        </physics>
      </joint>
      <link name='right_leg'>
        <pose frame=''>0 0 0 0 -0 0</pose>
        <inertial>
          <pose frame=''>0 0.14314 -0.207252 0 -0 0</pose>
          <mass>0.1</mass>
          <inertia>
            <ixx>0.001</ixx>
            <ixy>0</ixy>
            <ixz>0</ixz>
            <iyy>0.001</iyy>
            <iyz>0</iyz>
            <izz>0.001</izz>
          </inertia>
        </inertial>
        <collision name='collision'>
          <pose frame=''>-0.005 0.14314 -0.207252 0 1.56893 0</pose>
          <geometry>
            <cylinder>
              <radius>0.012209</radius>
              <length>0.3</length>
            </cylinder>
          </geometry>
          <surface>
            <friction>
              <ode>
                <mu>1</mu>
                <mu2>1</mu2>
              </ode>
              <torsional>
                <ode/>
              </torsional>
            </friction>
            <contact>
              <ode>
                <kp>1e+08</kp>
                <kd>1</kd>
                <max_vel>0.01</max_vel>
                <min_depth>0.001</min_depth>
              </ode>
            </contact>
            <bounce/>
          </surface>
          <max_contacts>10</max_contacts>
        </collision>
        <collision name='collision_bar'>
          <pose frame=''>0.00052 0.08503 -0.121187 0.501318 -0 0</pose>
          <geometry>
            <cylinder>
              <radius>0.00914984</radius>
              <length>0.176893</length>
            </cylinder>
          </geometry>
          <surface>
            <friction>
              <ode>
                <mu>1</mu>
                <mu2>1</mu2>
              </ode>
              <torsional>
                <ode/>
              </torsional>
            </friction>
            <contact>
              <ode>
                <kp>1e+08</kp>
                <kd>1</kd>
                <max_vel>0.01</max_vel>
                <min_depth>0.001</min_depth>
              </ode>
            </contact>
            <bounce/>
          </surface>
          <max_contacts>10</max_contacts>
        </collision>
        <visual name='base_link_right_leg'>
          <pose frame=''>0 0 0 0 -0 0</pose>
          <geometry>
            <mesh>
              <scale>1 1 1</scale>
              <uri>model://typhoon_h480/meshes/leg1_remeshed_v3.stl</uri>
            </mesh>
          </geometry>
          <material>
            <script>
              <name>Gazebo/DarkGrey</name>
              <uri>file://media/materials/scripts/gazebo.material</uri>
            </script>
          </material>
        </visual>
        <self_collide>0</self_collide>
        <kinematic>0</kinematic>
        <gravity>1</gravity>
      </link>
      <joint name='right_leg_joint' type='revolute'>
        <child>right_leg</child>
        <parent>base_link</parent>
        <pose frame=''>0.00026 0.040515 -0.048 0 -0 0</pose>
        <axis>
          <xyz>1 0 0</xyz>
          <limit>
            <lower>0</lower>
            <upper>1</upper>
            <effort>100</effort>
            <velocity>-1</velocity>
            <stiffness>1e+08</stiffness>
            <dissipation>1</dissipation>
          </limit>
          <dynamics>
            <damping>0.1</damping>
            <spring_reference>0</spring_reference>
            <spring_stiffness>0</spring_stiffness>
          </dynamics>
          <use_parent_model_frame>1</use_parent_model_frame>
        </axis>
        <physics>
          <ode>
            <implicit_spring_damper>1</implicit_spring_damper>
            <limit>
              <cfm>0</cfm>
              <erp>0.2</erp>
            </limit>
          </ode>
        </physics>
      </joint>
      <link name='typhoon_h480/imu_link'>
        <pose frame=''>0 0 0 0 -0 0</pose>
        <inertial>
          <pose frame=''>0 0 0 0 -0 0</pose>
          <mass>0.015</mass>
          <inertia>
            <ixx>1e-05</ixx>
            <ixy>0</ixy>
            <ixz>0</ixz>
            <iyy>1e-05</iyy>
            <iyz>0</iyz>
            <izz>1e-05</izz>
          </inertia>
        </inertial>
        <self_collide>0</self_collide>
        <kinematic>0</kinematic>
        <gravity>1</gravity>
      </link>
      <joint name='typhoon_h480/imu_joint' type='revolute'>
        <child>typhoon_h480/imu_link</child>
        <parent>base_link</parent>
        <axis>
          <xyz>1 0 0</xyz>
          <limit>
            <lower>0</lower>
            <upper>0</upper>
            <effort>0</effort>
            <velocity>0</velocity>
          </limit>
          <dynamics>
            <spring_reference>0</spring_reference>
            <spring_stiffness>0</spring_stiffness>
          </dynamics>
          <use_parent_model_frame>1</use_parent_model_frame>
        </axis>
      </joint>
      <link name='rotor_3'>
        <pose frame=''>0.211396 0.119762 0.082219 0 -0 0</pose>
        <inertial>
          <pose frame=''>0 0 0 0 -0 0</pose>
          <mass>0.005</mass>
          <inertia>
            <ixx>9.75e-07</ixx>
            <ixy>0</ixy>
            <ixz>0</ixz>
            <iyy>0.000273104</iyy>
            <iyz>0</iyz>
            <izz>0.000274004</izz>
          </inertia>
        </inertial>
        <collision name='rotor_3_collision'>
          <pose frame=''>0 0 0 0 -0 0</pose>
          <geometry>
            <cylinder>
              <length>0.005</length>
              <radius>0.128</radius>
            </cylinder>
          </geometry>
          <surface>
            <contact>
              <ode/>
            </contact>
            <friction>
              <ode/>
              <torsional>
                <ode/>
              </torsional>
            </friction>
            <bounce/>
          </surface>
          <max_contacts>10</max_contacts>
        </collision>
        <visual name='rotor_3_visual'>
          <pose frame=''>-0.211396 -0.119762 -0.082219 0 -0 0</pose>
          <geometry>
            <mesh>
              <scale>1 1 1</scale>
              <uri>model://typhoon_h480/meshes/prop_ccw_assembly_remeshed_v3.stl</uri>
            </mesh>
          </geometry>
          <material>
            <script>
              <name>Gazebo/Blue</name>
              <uri>file://media/materials/scripts/gazebo.material</uri>
            </script>
          </material>
        </visual>
        <gravity>1</gravity>
        <velocity_decay/>
        <self_collide>0</self_collide>
        <kinematic>0</kinematic>
      </link>
      <joint name='rotor_3_joint' type='revolute'>
        <child>rotor_3</child>
        <parent>base_link</parent>
        <axis>
          <xyz>0 0 1</xyz>
          <limit>
            <lower>-1e+16</lower>
            <upper>1e+16</upper>
            <effort>10</effort>
            <velocity>-1</velocity>
          </limit>
          <dynamics>
            <damping>0.005</damping>
            <spring_reference>0</spring_reference>
            <spring_stiffness>0</spring_stiffness>
          </dynamics>
          <use_parent_model_frame>1</use_parent_model_frame>
        </axis>
        <physics>
          <ode>
            <implicit_spring_damper>1</implicit_spring_damper>
            <limit>
              <cfm>0</cfm>
              <erp>0.2</erp>
            </limit>
          </ode>
        </physics>
      </joint>
      <link name='rotor_0'>
        <pose frame=''>-0.209396 0.122762 0.082219 0 -0 2.0944</pose>
        <inertial>
          <pose frame=''>0 0 0 0 -0 0</pose>
          <mass>0.005</mass>
          <inertia>
            <ixx>9.75e-07</ixx>
            <ixy>0</ixy>
            <ixz>0</ixz>
            <iyy>0.000273104</iyy>
            <iyz>0</iyz>
            <izz>0.000274004</izz>
          </inertia>
        </inertial>
        <collision name='rotor_0_collision'>
          <pose frame=''>0 0 0 0 -0 0</pose>
          <geometry>
            <cylinder>
              <length>0.005</length>
              <radius>0.128</radius>
            </cylinder>
          </geometry>
          <surface>
            <contact>
              <ode/>
            </contact>
            <friction>
              <ode/>
              <torsional>
                <ode/>
              </torsional>
            </friction>
            <bounce/>
          </surface>
          <max_contacts>10</max_contacts>
        </collision>
        <visual name='rotor_0_visual'>
          <pose frame=''>-0.211396 -0.119762 -0.082219 0 -0 0</pose>
          <geometry>
            <mesh>
              <scale>1 1 1</scale>
              <uri>model://typhoon_h480/meshes/prop_ccw_assembly_remeshed_v3.stl</uri>
            </mesh>
          </geometry>
          <material>
            <script>
              <name>Gazebo/Blue</name>
              <uri>file://media/materials/scripts/gazebo.material</uri>
            </script>
          </material>
        </visual>
        <gravity>1</gravity>
        <velocity_decay/>
        <self_collide>0</self_collide>
        <kinematic>0</kinematic>
      </link>
      <joint name='rotor_0_joint' type='revolute'>
        <child>rotor_0</child>
        <parent>base_link</parent>
        <axis>
          <xyz>0 0 1</xyz>
          <limit>
            <lower>-1e+16</lower>
            <upper>1e+16</upper>
            <effort>10</effort>
            <velocity>-1</velocity>
          </limit>
          <dynamics>
            <damping>0.005</damping>
            <spring_reference>0</spring_reference>
            <spring_stiffness>0</spring_stiffness>
          </dynamics>
          <use_parent_model_frame>1</use_parent_model_frame>
        </axis>
        <physics>
          <ode>
            <implicit_spring_damper>1</implicit_spring_damper>
            <limit>
              <cfm>0</cfm>
              <erp>0.2</erp>
            </limit>
          </ode>
        </physics>
      </joint>
      <link name='rotor_4'>
        <pose frame=''>-0.001879 0.242705 0.082217 0 -0 0</pose>
        <inertial>
          <pose frame=''>0 0 0 0 -0 0</pose>
          <mass>0.005</mass>
          <inertia>
            <ixx>9.75e-07</ixx>
            <ixy>0</ixy>
            <ixz>0</ixz>
            <iyy>0.000273104</iyy>
            <iyz>0</iyz>
            <izz>0.000274004</izz>
          </inertia>
        </inertial>
        <collision name='rotor_4_collision'>
          <pose frame=''>0 0 0 0 -0 0</pose>
          <geometry>
            <cylinder>
              <length>0.005</length>
              <radius>0.128</radius>
            </cylinder>
          </geometry>
          <surface>
            <contact>
              <ode/>
            </contact>
            <friction>
              <ode/>
              <torsional>
                <ode/>
              </torsional>
            </friction>
            <bounce/>
          </surface>
          <max_contacts>10</max_contacts>
        </collision>
        <visual name='rotor_4_visual'>
          <pose frame=''>0.001879 -0.242705 -0.082217 0 -0 0</pose>
          <geometry>
            <mesh>
              <scale>1 1 1</scale>
              <uri>model://typhoon_h480/meshes/prop_cw_assembly_remeshed_v3.stl</uri>
            </mesh>
          </geometry>
          <material>
            <script>
              <name>Gazebo/DarkGrey</name>
              <uri>file://media/materials/scripts/gazebo.material</uri>
            </script>
          </material>
        </visual>
        <gravity>1</gravity>
        <velocity_decay/>
        <self_collide>0</self_collide>
        <kinematic>0</kinematic>
      </link>
      <joint name='rotor_4_joint' type='revolute'>
        <child>rotor_4</child>
        <parent>base_link</parent>
        <axis>
          <xyz>0 0 1</xyz>
          <limit>
            <lower>-1e+16</lower>
            <upper>1e+16</upper>
            <effort>10</effort>
            <velocity>-1</velocity>
          </limit>
          <dynamics>
            <damping>0.005</damping>
            <spring_reference>0</spring_reference>
            <spring_stiffness>0</spring_stiffness>
          </dynamics>
          <use_parent_model_frame>1</use_parent_model_frame>
        </axis>
        <physics>
          <ode>
            <implicit_spring_damper>1</implicit_spring_damper>
            <limit>
              <cfm>0</cfm>
              <erp>0.2</erp>
            </limit>
          </ode>
        </physics>
      </joint>
      <link name='rotor_1'>
        <pose frame=''>0.211396 -0.119762 0.082219 0 0 -2.0944</pose>
        <inertial>
          <pose frame=''>0 0 0 0 -0 0</pose>
          <mass>0.005</mass>
          <inertia>
            <ixx>9.75e-07</ixx>
            <ixy>0</ixy>
            <ixz>0</ixz>
            <iyy>0.000273104</iyy>
            <iyz>0</iyz>
            <izz>0.000274004</izz>
          </inertia>
        </inertial>
        <collision name='rotor_1_collision'>
          <pose frame=''>0 0 0 0 -0 0</pose>
          <geometry>
            <cylinder>
              <length>0.005</length>
              <radius>0.128</radius>
            </cylinder>
          </geometry>
          <surface>
            <contact>
              <ode/>
            </contact>
            <friction>
              <ode/>
              <torsional>
                <ode/>
              </torsional>
            </friction>
            <bounce/>
          </surface>
          <max_contacts>10</max_contacts>
        </collision>
        <visual name='rotor_1_visual'>
          <pose frame=''>0.001879 -0.242705 -0.082217 0 -0 0</pose>
          <geometry>
            <mesh>
              <scale>1 1 1</scale>
              <uri>model://typhoon_h480/meshes/prop_cw_assembly_remeshed_v3.stl</uri>
            </mesh>
          </geometry>
          <material>
            <script>
              <name>Gazebo/DarkGrey</name>
              <uri>file://media/materials/scripts/gazebo.material</uri>
            </script>
          </material>
        </visual>
        <gravity>1</gravity>
        <velocity_decay/>
        <self_collide>0</self_collide>
        <kinematic>0</kinematic>
      </link>
      <joint name='rotor_1_joint' type='revolute'>
        <child>rotor_1</child>
        <parent>base_link</parent>
        <axis>
          <xyz>0 0 1</xyz>
          <limit>
            <lower>-1e+16</lower>
            <upper>1e+16</upper>
            <effort>10</effort>
            <velocity>-1</velocity>
          </limit>
          <dynamics>
            <damping>0.005</damping>
            <spring_reference>0</spring_reference>
            <spring_stiffness>0</spring_stiffness>
          </dynamics>
          <use_parent_model_frame>1</use_parent_model_frame>
        </axis>
        <physics>
          <ode>
            <implicit_spring_damper>1</implicit_spring_damper>
            <limit>
              <cfm>0</cfm>
              <erp>0.2</erp>
            </limit>
          </ode>
        </physics>
      </joint>
      <link name='rotor_5'>
        <pose frame=''>-0.001879 -0.242705 0.082217 0 0 -2.0944</pose>
        <inertial>
          <pose frame=''>0 0 0 0 -0 0</pose>
          <mass>0.005</mass>
          <inertia>
            <ixx>9.75e-07</ixx>
            <ixy>0</ixy>
            <ixz>0</ixz>
            <iyy>0.000273104</iyy>
            <iyz>0</iyz>
            <izz>0.000274004</izz>
          </inertia>
        </inertial>
        <collision name='rotor_5_collision'>
          <pose frame=''>0 0 0 0 -0 0</pose>
          <geometry>
            <cylinder>
              <length>0.005</length>
              <radius>0.128</radius>
            </cylinder>
          </geometry>
          <surface>
            <contact>
              <ode/>
            </contact>
            <friction>
              <ode/>
              <torsional>
                <ode/>
              </torsional>
            </friction>
            <bounce/>
          </surface>
          <max_contacts>10</max_contacts>
        </collision>
        <visual name='rotor_5_visual'>
          <pose frame=''>-0.211396 -0.119762 -0.082219 0 -0 0</pose>
          <geometry>
            <mesh>
              <scale>1 1 1</scale>
              <uri>model://typhoon_h480/meshes/prop_ccw_assembly_remeshed_v3.stl</uri>
            </mesh>
          </geometry>
          <material>
            <script>
              <name>Gazebo/Blue</name>
              <uri>file://media/materials/scripts/gazebo.material</uri>
            </script>
          </material>
        </visual>
        <gravity>1</gravity>
        <velocity_decay/>
        <self_collide>0</self_collide>
        <kinematic>0</kinematic>
      </link>
      <joint name='rotor_5_joint' type='revolute'>
        <child>rotor_5</child>
        <parent>base_link</parent>
        <axis>
          <xyz>0 0 1</xyz>
          <limit>
            <lower>-1e+16</lower>
            <upper>1e+16</upper>
            <effort>10</effort>
            <velocity>-1</velocity>
          </limit>
          <dynamics>
            <damping>0.005</damping>
            <spring_reference>0</spring_reference>
            <spring_stiffness>0</spring_stiffness>
          </dynamics>
          <use_parent_model_frame>1</use_parent_model_frame>
        </axis>
        <physics>
          <ode>
            <implicit_spring_damper>1</implicit_spring_damper>
            <limit>
              <cfm>0</cfm>
              <erp>0.2</erp>
            </limit>
          </ode>
        </physics>
      </joint>
      <link name='rotor_2'>
        <pose frame=''>-0.209396 -0.122762 0.082219 0 -0 2.0944</pose>
        <inertial>
          <pose frame=''>0 0 0 0 -0 0</pose>
          <mass>0.005</mass>
          <inertia>
            <ixx>9.75e-07</ixx>
            <ixy>0</ixy>
            <ixz>0</ixz>
            <iyy>0.000273104</iyy>
            <iyz>0</iyz>
            <izz>0.000274004</izz>
          </inertia>
        </inertial>
        <collision name='rotor_2_collision'>
          <pose frame=''>0 0 0 0 -0 0</pose>
          <geometry>
            <cylinder>
              <length>0.005</length>
              <radius>0.128</radius>
            </cylinder>
          </geometry>
          <surface>
            <contact>
              <ode/>
            </contact>
            <friction>
              <ode/>
              <torsional>
                <ode/>
              </torsional>
            </friction>
            <bounce/>
          </surface>
          <max_contacts>10</max_contacts>
        </collision>
        <visual name='rotor_2_visual'>
          <pose frame=''>0.001879 -0.242705 -0.082217 0 -0 0</pose>
          <geometry>
            <mesh>
              <scale>1 1 1</scale>
              <uri>model://typhoon_h480/meshes/prop_cw_assembly_remeshed_v3.stl</uri>
            </mesh>
          </geometry>
          <material>
            <script>
              <name>Gazebo/DarkGrey</name>
              <uri>file://media/materials/scripts/gazebo.material</uri>
            </script>
          </material>
        </visual>
        <gravity>1</gravity>
        <velocity_decay/>
        <self_collide>0</self_collide>
        <kinematic>0</kinematic>
      </link>
      <joint name='rotor_2_joint' type='revolute'>
        <child>rotor_2</child>
        <parent>base_link</parent>
        <axis>
          <xyz>0 0 1</xyz>
          <limit>
            <lower>-1e+16</lower>
            <upper>1e+16</upper>
            <effort>10</effort>
            <velocity>-1</velocity>
          </limit>
          <dynamics>
            <damping>0.005</damping>
            <spring_reference>0</spring_reference>
            <spring_stiffness>0</spring_stiffness>
          </dynamics>
          <use_parent_model_frame>1</use_parent_model_frame>
        </axis>
        <physics>
          <ode>
            <implicit_spring_damper>1</implicit_spring_damper>
            <limit>
              <cfm>0</cfm>
              <erp>0.2</erp>
            </limit>
          </ode>
        </physics>
      </joint>
      <link name='sonar::link'>
        <pose frame=''>0.08 0 -0.03 0 -0 3.14159</pose>
        <inertial>
          <pose frame=''>0 0 0 0 -0 0</pose>
          <mass>1e-15</mass>
          <inertia>
            <ixx>2.08333e-07</ixx>
            <ixy>0</ixy>
            <ixz>0</ixz>
            <iyy>2.08333e-07</iyy>
            <iyz>0</iyz>
            <izz>4.16667e-08</izz>
          </inertia>
        </inertial>
        <visual name='visual'>
          <geometry>
            <box>
              <size>0.005 0.015 0.005</size>
            </box>
          </geometry>
          <material>
            <script>
              <name>Gazebo/Black</name>
              <uri>__default__</uri>
            </script>
          </material>
        </visual>
        <sensor name='sonar' type='sonar'>
          <pose frame=''>0 0 0 0 1.57 0</pose>
          <sonar>
            <min>0.02</min>
            <max>5</max>
            <radius>1.33974</radius>
          </sonar>
          <plugin name='SonarPlugin' filename='libgazebo_sonar_plugin.so'>
            <robotNamespace/>
          </plugin>
          <always_on>1</always_on>
          <update_rate>20</update_rate>
          <visualize>1</visualize>
        </sensor>
        <self_collide>0</self_collide>
        <kinematic>0</kinematic>
        <gravity>1</gravity>
      </link>
      <joint name='sonar_joint' type='revolute'>
        <child>sonar::link</child>
        <parent>typhoon_h480::base_link</parent>
        <axis>
          <xyz>0 0 1</xyz>
          <limit>
            <upper>0</upper>
            <lower>0</lower>
          </limit>
          <use_parent_model_frame>0</use_parent_model_frame>
          <dynamics>
            <spring_reference>0</spring_reference>
            <spring_stiffness>0</spring_stiffness>
          </dynamics>
        </axis>
      </joint>
      <link name='gps::link'>
        <pose frame=''>0 0 0 0 -0 0</pose>
        <inertial>
          <pose frame=''>0 0 0 0 -0 0</pose>
          <mass>0.015</mass>
          <inertia>
            <ixx>1e-05</ixx>
            <ixy>0</ixy>
            <ixz>0</ixz>
            <iyy>1e-05</iyy>
            <iyz>0</iyz>
            <izz>1e-05</izz>
          </inertia>
        </inertial>
        <visual name='visual'>
          <geometry>
            <cylinder>
              <radius>0.01</radius>
              <length>0.002</length>
            </cylinder>
          </geometry>
          <material>
            <script>
              <name>Gazebo/Black</name>
              <uri>__default__</uri>
            </script>
          </material>
        </visual>
        <sensor name='gps' type='gps'>
          <pose frame=''>0 0 0 0 -0 0</pose>
          <update_rate>5</update_rate>
          <always_on>1</always_on>
          <visualize>0</visualize>
          <plugin name='gps_plugin' filename='libgazebo_gps_plugin.so'>
            <robotNamespace/>
            <gpsNoise>true</gpsNoise>
            <gpsXYRandomWalk>2.0</gpsXYRandomWalk>
            <gpsZRandomWalk>4.0</gpsZRandomWalk>
            <gpsXYNoiseDensity>2.0e-4</gpsXYNoiseDensity>
            <gpsZNoiseDensity>4.0e-4</gpsZNoiseDensity>
            <gpsVXYNoiseDensity>0.2</gpsVXYNoiseDensity>
            <gpsVZNoiseDensity>0.4</gpsVZNoiseDensity>
          </plugin>
        </sensor>
        <self_collide>0</self_collide>
        <kinematic>0</kinematic>
        <gravity>1</gravity>
      </link>
      <joint name='gps_joint' type='fixed'>
        <child>gps::link</child>
        <parent>base_link</parent>
      </joint>
      <plugin name='rosbag' filename='libgazebo_multirotor_base_plugin.so'>
        <robotNamespace/>
        <linkName>base_link</linkName>
        <rotorVelocitySlowdownSim>10</rotorVelocitySlowdownSim>
      </plugin>
      <plugin name='front_right_motor_model' filename='libgazebo_motor_model.so'>
        <robotNamespace/>
        <jointName>rotor_0_joint</jointName>
        <linkName>rotor_0</linkName>
        <turningDirection>cw</turningDirection>
        <timeConstantUp>0.0125</timeConstantUp>
        <timeConstantDown>0.025</timeConstantDown>
        <maxRotVelocity>1500</maxRotVelocity>
        <motorConstant>8.54858e-06</motorConstant>
        <momentConstant>0.06</momentConstant>
        <commandSubTopic>/gazebo/command/motor_speed</commandSubTopic>
        <motorNumber>5</motorNumber>
        <rotorDragCoefficient>0.000806428</rotorDragCoefficient>
        <rollingMomentCoefficient>1e-06</rollingMomentCoefficient>
        <motorSpeedPubTopic>/motor_speed/5</motorSpeedPubTopic>
        <rotorVelocitySlowdownSim>10</rotorVelocitySlowdownSim>
      </plugin>
      <plugin name='back_left_motor_model' filename='libgazebo_motor_model.so'>
        <robotNamespace/>
        <jointName>rotor_1_joint</jointName>
        <linkName>rotor_1</linkName>
        <turningDirection>ccw</turningDirection>
        <timeConstantUp>0.0125</timeConstantUp>
        <timeConstantDown>0.025</timeConstantDown>
        <maxRotVelocity>1500</maxRotVelocity>
        <motorConstant>8.54858e-06</motorConstant>
        <momentConstant>0.06</momentConstant>
        <commandSubTopic>/gazebo/command/motor_speed</commandSubTopic>
        <motorNumber>4</motorNumber>
        <rotorDragCoefficient>0.000806428</rotorDragCoefficient>
        <rollingMomentCoefficient>1e-06</rollingMomentCoefficient>
        <motorSpeedPubTopic>/motor_speed/4</motorSpeedPubTopic>
        <rotorVelocitySlowdownSim>10</rotorVelocitySlowdownSim>
      </plugin>
      <plugin name='front_left_motor_model' filename='libgazebo_motor_model.so'>
        <robotNamespace/>
        <jointName>rotor_2_joint</jointName>
        <linkName>rotor_2</linkName>
        <turningDirection>ccw</turningDirection>
        <timeConstantUp>0.0125</timeConstantUp>
        <timeConstantDown>0.025</timeConstantDown>
        <maxRotVelocity>1500</maxRotVelocity>
        <motorConstant>8.54858e-06</motorConstant>
        <momentConstant>0.06</momentConstant>
        <commandSubTopic>/gazebo/command/motor_speed</commandSubTopic>
        <motorNumber>3</motorNumber>
        <rotorDragCoefficient>0.000806428</rotorDragCoefficient>
        <rollingMomentCoefficient>1e-06</rollingMomentCoefficient>
        <motorSpeedPubTopic>/motor_speed/3</motorSpeedPubTopic>
        <rotorVelocitySlowdownSim>10</rotorVelocitySlowdownSim>
      </plugin>
      <plugin name='back_right_motor_model' filename='libgazebo_motor_model.so'>
        <robotNamespace/>
        <jointName>rotor_3_joint</jointName>
        <linkName>rotor_3</linkName>
        <turningDirection>cw</turningDirection>
        <timeConstantUp>0.0125</timeConstantUp>
        <timeConstantDown>0.025</timeConstantDown>
        <maxRotVelocity>1500</maxRotVelocity>
        <motorConstant>8.54858e-06</motorConstant>
        <momentConstant>0.06</momentConstant>
        <commandSubTopic>/gazebo/command/motor_speed</commandSubTopic>
        <motorNumber>2</motorNumber>
        <rotorDragCoefficient>0.000806428</rotorDragCoefficient>
        <rollingMomentCoefficient>1e-06</rollingMomentCoefficient>
        <motorSpeedPubTopic>/motor_speed/2</motorSpeedPubTopic>
        <rotorVelocitySlowdownSim>10</rotorVelocitySlowdownSim>
      </plugin>
      <plugin name='back_left_motor_model' filename='libgazebo_motor_model.so'>
        <robotNamespace/>
        <jointName>rotor_4_joint</jointName>
        <linkName>rotor_4</linkName>
        <turningDirection>ccw</turningDirection>
        <timeConstantUp>0.0125</timeConstantUp>
        <timeConstantDown>0.025</timeConstantDown>
        <maxRotVelocity>1500</maxRotVelocity>
        <motorConstant>8.54858e-06</motorConstant>
        <momentConstant>0.06</momentConstant>
        <commandSubTopic>/gazebo/command/motor_speed</commandSubTopic>
        <motorNumber>1</motorNumber>
        <rotorDragCoefficient>0.000806428</rotorDragCoefficient>
        <rollingMomentCoefficient>1e-06</rollingMomentCoefficient>
        <motorSpeedPubTopic>/motor_speed/1</motorSpeedPubTopic>
        <rotorVelocitySlowdownSim>10</rotorVelocitySlowdownSim>
      </plugin>
      <plugin name='front_left_motor_model' filename='libgazebo_motor_model.so'>
        <robotNamespace/>
        <jointName>rotor_5_joint</jointName>
        <linkName>rotor_5</linkName>
        <turningDirection>cw</turningDirection>
        <timeConstantUp>0.0125</timeConstantUp>
        <timeConstantDown>0.025</timeConstantDown>
        <maxRotVelocity>1500</maxRotVelocity>
        <motorConstant>8.54858e-06</motorConstant>
        <momentConstant>0.06</momentConstant>
        <commandSubTopic>/gazebo/command/motor_speed</commandSubTopic>
        <motorNumber>0</motorNumber>
        <rotorDragCoefficient>0.000806428</rotorDragCoefficient>
        <rollingMomentCoefficient>1e-06</rollingMomentCoefficient>
        <motorSpeedPubTopic>/motor_speed/0</motorSpeedPubTopic>
        <rotorVelocitySlowdownSim>10</rotorVelocitySlowdownSim>
      </plugin>
      <plugin name='groundtruth_plugin' filename='libgazebo_groundtruth_plugin.so'>
        <robotNamespace/>
      </plugin>
      <plugin name='magnetometer_plugin' filename='libgazebo_magnetometer_plugin.so'>
        <robotNamespace/>
        <pubRate>100</pubRate>
        <noiseDensity>0.0004</noiseDensity>
        <randomWalk>6.4e-06</randomWalk>
        <biasCorrelationTime>600</biasCorrelationTime>
        <magTopic>/mag</magTopic>
      </plugin>
      <plugin name='barometer_plugin' filename='libgazebo_barometer_plugin.so'>
        <robotNamespace/>
        <pubRate>50</pubRate>
        <baroTopic>/baro</baroTopic>
      </plugin>
      <plugin name='mavlink_interface' filename='libgazebo_mavlink_interface.so'>
        <robotNamespace/>
        <imuSubTopic>/imu</imuSubTopic>
        <magSubTopic>/mag</magSubTopic>
        <baroSubTopic>/baro</baroSubTopic>
        <mavlink_addr>INADDR_ANY</mavlink_addr>
        <mavlink_udp_port>14560</mavlink_udp_port>
        <serialEnabled>false</serialEnabled>
        <serialDevice>/dev/ttyACM0</serialDevice>
        <baudRate>921600</baudRate>
        <qgc_addr>INADDR_ANY</qgc_addr>
        <qgc_udp_port>14550</qgc_udp_port>
        <sdk_addr>INADDR_ANY</sdk_addr>
        <sdk_udp_port>14540</sdk_udp_port>
        <hil_mode>false</hil_mode>
        <hil_state_level>false</hil_state_level>
        <enable_lockstep>true</enable_lockstep>
        <use_tcp>true</use_tcp>
        <motorSpeedCommandPubTopic>/gazebo/command/motor_speed</motorSpeedCommandPubTopic>
        <control_channels>
          <channel name='rotor0'>
            <input_index>0</input_index>
            <input_offset>0</input_offset>
            <input_scaling>1500</input_scaling>
            <zero_position_disarmed>0</zero_position_disarmed>
            <zero_position_armed>100</zero_position_armed>
            <joint_control_type>velocity</joint_control_type>
          </channel>
          <channel name='rotor1'>
            <input_index>1</input_index>
            <input_offset>0</input_offset>
            <input_scaling>1500</input_scaling>
            <zero_position_disarmed>0</zero_position_disarmed>
            <zero_position_armed>100</zero_position_armed>
            <joint_control_type>velocity</joint_control_type>
          </channel>
          <channel name='rotor2'>
            <input_index>2</input_index>
            <input_offset>0</input_offset>
            <input_scaling>1500</input_scaling>
            <zero_position_disarmed>0</zero_position_disarmed>
            <zero_position_armed>100</zero_position_armed>
            <joint_control_type>velocity</joint_control_type>
          </channel>
          <channel name='rotor3'>
            <input_index>3</input_index>
            <input_offset>0</input_offset>
            <input_scaling>1500</input_scaling>
            <zero_position_disarmed>0</zero_position_disarmed>
            <zero_position_armed>100</zero_position_armed>
            <joint_control_type>velocity</joint_control_type>
          </channel>
          <channel name='rotor4'>
            <input_index>4</input_index>
            <input_offset>0</input_offset>
            <input_scaling>1500</input_scaling>
            <zero_position_disarmed>0</zero_position_disarmed>
            <zero_position_armed>100</zero_position_armed>
            <joint_control_type>velocity</joint_control_type>
          </channel>
          <channel name='rotor5'>
            <input_index>5</input_index>
            <input_offset>0</input_offset>
            <input_scaling>1500</input_scaling>
            <zero_position_disarmed>0</zero_position_disarmed>
            <zero_position_armed>100</zero_position_armed>
            <joint_control_type>velocity</joint_control_type>
          </channel>
          <channel name='gimbal_roll'>
            <input_index>6</input_index>
            <input_offset>0</input_offset>
            <input_scaling>-3.1415</input_scaling>
            <zero_position_disarmed>0</zero_position_disarmed>
            <zero_position_armed>0</zero_position_armed>
            <joint_control_type>position_gztopic</joint_control_type>
            <gztopic>/gimbal_roll_cmd</gztopic>
            <joint_name>typhoon_h480::cgo3_camera_joint</joint_name>
          </channel>
          <channel name='gimbal_pitch'>
            <input_index>7</input_index>
            <input_offset>0</input_offset>
            <input_scaling>-3.1415</input_scaling>
            <zero_position_disarmed>0</zero_position_disarmed>
            <zero_position_armed>0</zero_position_armed>
            <joint_control_type>position_gztopic</joint_control_type>
            <gztopic>/gimbal_pitch_cmd</gztopic>
            <joint_name>typhoon_h480::cgo3_camera_joint</joint_name>
          </channel>
          <channel name='gimbal_yaw'>
            <input_index>8</input_index>
            <input_offset>0</input_offset>
            <input_scaling>-3.1415</input_scaling>
            <zero_position_disarmed>0</zero_position_disarmed>
            <zero_position_armed>0</zero_position_armed>
            <joint_control_type>position_gztopic</joint_control_type>
            <gztopic>/gimbal_yaw_cmd</gztopic>
            <joint_name>typhoon_h480::cgo3_vertical_arm_joint</joint_name>
          </channel>
          <channel name='left_leg'>
            <input_index>9</input_index>
            <input_offset>1</input_offset>
            <input_scaling>0.5</input_scaling>
            <zero_position_disarmed>0</zero_position_disarmed>
            <zero_position_armed>0</zero_position_armed>
            <joint_control_type>position</joint_control_type>
            <joint_control_pid>
              <p>3.5</p>
              <i>0.5</i>
              <d>0</d>
              <iMax>4</iMax>
              <iMin>-4</iMin>
              <cmdMax>6</cmdMax>
              <cmdMin>-6</cmdMin>
            </joint_control_pid>
            <joint_name>left_leg_joint</joint_name>
          </channel>
          <channel name='right_leg'>
            <input_index>10</input_index>
            <input_offset>1</input_offset>
            <input_scaling>0.5</input_scaling>
            <zero_position_disarmed>0</zero_position_disarmed>
            <zero_position_armed>0</zero_position_armed>
            <joint_control_type>position</joint_control_type>
            <joint_control_pid>
              <p>3.5</p>
              <i>0.5</i>
              <d>0</d>
              <iMax>4</iMax>
              <iMin>-4</iMin>
              <cmdMax>6</cmdMax>
              <cmdMin>-6</cmdMin>
            </joint_control_pid>
            <joint_name>right_leg_joint</joint_name>
          </channel>
        </control_channels>
      </plugin>
      <static>0</static>
      <plugin name='gazebo_imu_plugin' filename='libgazebo_imu_plugin.so'>
        <robotNamespace/>
        <linkName>typhoon_h480/imu_link</linkName>
        <imuTopic>/imu</imuTopic>
        <gyroscopeNoiseDensity>0.0003394</gyroscopeNoiseDensity>
        <gyroscopeRandomWalk>3.8785e-05</gyroscopeRandomWalk>
        <gyroscopeBiasCorrelationTime>1000.0</gyroscopeBiasCorrelationTime>
        <gyroscopeTurnOnBiasSigma>0.0087</gyroscopeTurnOnBiasSigma>
        <accelerometerNoiseDensity>0.004</accelerometerNoiseDensity>
        <accelerometerRandomWalk>0.006</accelerometerRandomWalk>
        <accelerometerBiasCorrelationTime>300.0</accelerometerBiasCorrelationTime>
        <accelerometerTurnOnBiasSigma>0.196</accelerometerTurnOnBiasSigma>
      </plugin>
      <plugin name='gimbal_controller' filename='libgazebo_gimbal_controller_plugin.so'>
        <joint_yaw>typhoon_h480::cgo3_vertical_arm_joint</joint_yaw>
        <joint_roll>typhoon_h480::cgo3_horizontal_arm_joint</joint_roll>
        <joint_pitch>typhoon_h480::cgo3_camera_joint</joint_pitch>
        <control_gimbal_channels>
          <channel>
            <joint_control_pid>
              <p>0.6</p>
              <i>0.1</i>
              <d>0.02</d>
              <iMax>0</iMax>
              <iMin>0</iMin>
              <cmdMax>1.0</cmdMax>
              <cmdMin>-1.0</cmdMin>
            </joint_control_pid>
            <joint_axis>joint_yaw</joint_axis>
          </channel>
          <channel>
            <joint_control_pid>
              <p>0.8</p>
              <i>0.035</i>
              <d>0.02</d>
              <iMax>0</iMax>
              <iMin>0</iMin>
              <cmdMax>0.3</cmdMax>
              <cmdMin>-0.3</cmdMin>
            </joint_control_pid>
            <joint_axis>joint_roll</joint_axis>
          </channel>
          <channel>
            <joint_control_pid>
              <p>2.068</p>
              <i>0.01245</i>
              <d>0.01</d>
              <iMax>0</iMax>
              <iMin>0</iMin>
              <cmdMax>0.3</cmdMax>
              <cmdMin>-0.3</cmdMin>
            </joint_control_pid>
            <joint_axis>joint_pitch</joint_axis>
          </channel>
        </control_gimbal_channels>
        <gimbal_imu>camera_imu</gimbal_imu>
      </plugin>
    </model>
    <model name='gramado'>
      <static>1</static>
      <link name='link'>
        <collision name='collision'>
          <geometry>
            <box>
              <size>20 20 0.1</size>
            </box>
          </geometry>
          <max_contacts>10</max_contacts>
          <surface>
            <contact>
              <ode/>
            </contact>
            <bounce/>
            <friction>
              <torsional>
                <ode/>
              </torsional>
              <ode/>
            </friction>
          </surface>
        </collision>
        <visual name='visual'>
          <cast_shadows>0</cast_shadows>
          <geometry>
            <box>
              <size>20 20 0.1</size>
            </box>
          </geometry>
          <material>
            <script>
              <uri>model://gramado/materials/scripts</uri>
              <uri>model://gramado/materials/textures</uri>
              <name>vrc/asphalt</name>
            </script>
          </material>
        </visual>
        <self_collide>0</self_collide>
        <kinematic>0</kinematic>
        <gravity>1</gravity>
      </link>
      <pose frame=''>0.992834 -0.330124 0 0 -0 0</pose>
    </model>
    <model name='Painel Solar'>
      <static>1</static>
      <link name='link'>
        <visual name='painel_solar'>
          <cast_shadows>1</cast_shadows>
          <pose frame=''>0 0 0 0 -0 0</pose>
          <geometry>
            <mesh>
              <uri>model://painel_solar/meshes/solar.dae</uri>
              <scale>1 1 1</scale>
            </mesh>
          </geometry>
        </visual>
        <self_collide>0</self_collide>
        <kinematic>0</kinematic>
        <gravity>1</gravity>
      </link>
      <pose frame=''>2.60345 0.121386 0 0 -0 0</pose>
    </model>
    <model name='Painel Solar_0'>
      <static>1</static>
      <link name='link'>
        <visual name='painel_solar'>
          <cast_shadows>1</cast_shadows>
          <pose frame=''>0 0 0 0 -0 0</pose>
          <geometry>
            <mesh>
              <uri>model://painel_solar/meshes/solar.dae</uri>
              <scale>1 1 1</scale>
            </mesh>
          </geometry>
        </visual>
        <self_collide>0</self_collide>
        <kinematic>0</kinematic>
        <gravity>1</gravity>
      </link>
      <pose frame=''>8.87582 0.227139 0 0 -0 0</pose>
    </model>
    <model name='Painel Solar_1'>
      <static>1</static>
      <link name='link'>
        <visual name='painel_solar'>
          <cast_shadows>1</cast_shadows>
          <pose frame=''>0 0 0 0 -0 0</pose>
          <geometry>
            <mesh>
              <uri>model://painel_solar/meshes/solar.dae</uri>
              <scale>1 1 1</scale>
            </mesh>
          </geometry>
        </visual>
        <self_collide>0</self_collide>
        <kinematic>0</kinematic>
        <gravity>1</gravity>
      </link>
      <pose frame=''>-4.25507 -4.27703 0 0 -0 0</pose>
    </model>
    <model name='Painel Solar_2'>
      <static>1</static>
      <link name='link'>
        <visual name='painel_solar'>
          <cast_shadows>1</cast_shadows>
          <pose frame=''>0 0 0 0 -0 0</pose>
          <geometry>
            <mesh>
              <uri>model://painel_solar/meshes/solar.dae</uri>
              <scale>1 1 1</scale>
            </mesh>
          </geometry>
        </visual>
        <self_collide>0</self_collide>
        <kinematic>0</kinematic>
        <gravity>1</gravity>
      </link>
      <pose frame=''>2.06836 -4.29434 0 0 -0 0</pose>
    </model>
    <model name='Painel Solar_3'>
      <static>1</static>
      <link name='link'>
        <visual name='painel_solar'>
          <cast_shadows>1</cast_shadows>
          <pose frame=''>0 0 0 0 -0 0</pose>
          <geometry>
            <mesh>
              <uri>model://painel_solar/meshes/solar.dae</uri>
              <scale>1 1 1</scale>
            </mesh>
          </geometry>
        </visual>
        <self_collide>0</self_collide>
        <kinematic>0</kinematic>
        <gravity>1</gravity>
      </link>
      <pose frame=''>8.58987 -4.3117 0 0 -0 0</pose>
    </model>
    <model name='Painel Solar_4'>
      <static>1</static>
      <link name='link'>
        <visual name='painel_solar'>
          <cast_shadows>1</cast_shadows>
          <pose frame=''>0 0 0 0 -0 0</pose>
          <geometry>
            <mesh>
              <uri>model://painel_solar/meshes/solar.dae</uri>
              <scale>1 1 1</scale>
            </mesh>
          </geometry>
        </visual>
        <self_collide>0</self_collide>
        <kinematic>0</kinematic>
        <gravity>1</gravity>
      </link>
      <pose frame=''>-4.37608 -8.16933 0 0 -0 0</pose>
    </model>
    <model name='Painel Solar_5'>
      <static>1</static>
      <link name='link'>
        <visual name='painel_solar'>
          <cast_shadows>1</cast_shadows>
          <pose frame=''>0 0 0 0 -0 0</pose>
          <geometry>
            <mesh>
              <uri>model://painel_solar/meshes/solar.dae</uri>
              <scale>1 1 1</scale>
            </mesh>
          </geometry>
        </visual>
        <self_collide>0</self_collide>
        <kinematic>0</kinematic>
        <gravity>1</gravity>
      </link>
      <pose frame=''>2.06823 -8.23086 0 0 -0 0</pose>
    </model>
    <model name='Painel Solar_6'>
      <static>1</static>
      <link name='link'>
        <visual name='painel_solar'>
          <cast_shadows>1</cast_shadows>
          <pose frame=''>0 0 0 0 -0 0</pose>
          <geometry>
            <mesh>
              <uri>model://painel_solar/meshes/solar.dae</uri>
              <scale>1 1 1</scale>
            </mesh>
          </geometry>
        </visual>
        <self_collide>0</self_collide>
        <kinematic>0</kinematic>
        <gravity>1</gravity>
      </link>
      <pose frame=''>8.55502 -8.22212 0 0 -0 0</pose>
    </model>
    <model name='Painel Solar_7'>
      <static>1</static>
      <link name='link'>
        <visual name='painel_solar'>
          <cast_shadows>1</cast_shadows>
          <pose frame=''>0 0 0 0 -0 0</pose>
          <geometry>
            <mesh>
              <uri>model://painel_solar/meshes/solar.dae</uri>
              <scale>1 1 1</scale>
            </mesh>
          </geometry>
        </visual>
        <self_collide>0</self_collide>
        <kinematic>0</kinematic>
        <gravity>1</gravity>
      </link>
      <pose frame=''>-4.30602 -11.9474 0 0 -0 0</pose>
    </model>
    <model name='Painel Solar_8'>
      <static>1</static>
      <link name='link'>
        <visual name='painel_solar'>
          <cast_shadows>1</cast_shadows>
          <pose frame=''>0 0 0 0 -0 0</pose>
          <geometry>
            <mesh>
              <uri>model://painel_solar/meshes/solar.dae</uri>
              <scale>1 1 1</scale>
            </mesh>
          </geometry>
        </visual>
        <self_collide>0</self_collide>
        <kinematic>0</kinematic>
        <gravity>1</gravity>
      </link>
      <pose frame=''>2.19703 -12.0249 0 0 -0 0</pose>
    </model>
    <model name='Painel Solar_9'>
      <static>1</static>
      <link name='link'>
        <visual name='painel_solar'>
          <cast_shadows>1</cast_shadows>
          <pose frame=''>0 0 0 0 -0 0</pose>
          <geometry>
            <mesh>
              <uri>model://painel_solar/meshes/solar.dae</uri>
              <scale>1 1 1</scale>
            </mesh>
          </geometry>
        </visual>
        <self_collide>0</self_collide>
        <kinematic>0</kinematic>
        <gravity>1</gravity>
      </link>
      <pose frame=''>8.53753 -12.0539 0 0 -0 0</pose>
    </model>
    <model name='Painel Solar_10'>
      <static>1</static>
      <link name='link'>
        <visual name='painel_solar'>
          <cast_shadows>1</cast_shadows>
          <pose frame=''>0 0 0 0 -0 0</pose>
          <geometry>
            <mesh>
              <uri>model://painel_solar/meshes/solar.dae</uri>
              <scale>1 1 1</scale>
            </mesh>
          </geometry>
        </visual>
        <self_collide>0</self_collide>
        <kinematic>0</kinematic>
        <gravity>1</gravity>
      </link>
      <pose frame=''>-4.32912 -15.4665 0 0 -0 0</pose>
    </model>
    <model name='Painel Solar_11'>
      <static>1</static>
      <link name='link'>
        <visual name='painel_solar'>
          <cast_shadows>1</cast_shadows>
          <pose frame=''>0 0 0 0 -0 0</pose>
          <geometry>
            <mesh>
              <uri>model://painel_solar/meshes/solar.dae</uri>
              <scale>1 1 1</scale>
            </mesh>
          </geometry>
        </visual>
        <self_collide>0</self_collide>
        <kinematic>0</kinematic>
        <gravity>1</gravity>
      </link>
      <pose frame=''>2.12919 -15.4647 0 0 -0 0</pose>
    </model>
    <model name='Painel Solar_12'>
      <static>1</static>
      <link name='link'>
        <visual name='painel_solar'>
          <cast_shadows>1</cast_shadows>
          <pose frame=''>0 0 0 0 -0 0</pose>
          <geometry>
            <mesh>
              <uri>model://painel_solar/meshes/solar.dae</uri>
              <scale>1 1 1</scale>
            </mesh>
          </geometry>
        </visual>
        <self_collide>0</self_collide>
        <kinematic>0</kinematic>
        <gravity>1</gravity>
      </link>
      <pose frame=''>8.56858 -15.5025 0 0 -0 0</pose>
    </model>
    <state world_name='default'>
      <sim_time>620 680000000</sim_time>
      <real_time>624 699450507</real_time>
      <wall_time>1622758508 951455675</wall_time>
      <iterations>155170</iterations>
      <model name='Painel Solar'>
        <pose frame=''>2.60345 0.121386 0 0 -0 0</pose>
        <scale>1 1 1</scale>
        <link name='link'>
          <pose frame=''>2.60345 0.121386 0 0 -0 0</pose>
          <velocity>0 0 0 0 -0 0</velocity>
          <acceleration>0 0 0 0 -0 0</acceleration>
          <wrench>0 0 0 0 -0 0</wrench>
        </link>
      </model>
      <model name='Painel Solar_0'>
        <pose frame=''>8.93453 0.073177 0 0 -0 0</pose>
        <scale>1 1 1</scale>
        <link name='link'>
          <pose frame=''>8.93453 0.073177 0 0 -0 0</pose>
          <velocity>0 0 0 0 -0 0</velocity>
          <acceleration>0 0 0 0 -0 0</acceleration>
          <wrench>0 0 0 0 -0 0</wrench>
        </link>
      </model>
      <model name='Painel Solar_1'>
        <pose frame=''>-4.25507 -4.27703 0 0 -0 0</pose>
        <scale>1 1 1</scale>
        <link name='link'>
          <pose frame=''>-4.25507 -4.27703 0 0 -0 0</pose>
          <velocity>0 0 0 0 -0 0</velocity>
          <acceleration>0 0 0 0 -0 0</acceleration>
          <wrench>0 0 0 0 -0 0</wrench>
        </link>
      </model>
      <model name='Painel Solar_10'>
        <pose frame=''>-4.32912 -15.4665 0 0 -0 0</pose>
        <scale>1 1 1</scale>
        <link name='link'>
          <pose frame=''>-4.32912 -15.4665 0 0 -0 0</pose>
          <velocity>0 0 0 0 -0 0</velocity>
          <acceleration>0 0 0 0 -0 0</acceleration>
          <wrench>0 0 0 0 -0 0</wrench>
        </link>
      </model>
      <model name='Painel Solar_11'>
        <pose frame=''>2.12919 -15.4647 0 0 -0 0</pose>
        <scale>1 1 1</scale>
        <link name='link'>
          <pose frame=''>2.12919 -15.4647 0 0 -0 0</pose>
          <velocity>0 0 0 0 -0 0</velocity>
          <acceleration>0 0 0 0 -0 0</acceleration>
          <wrench>0 0 0 0 -0 0</wrench>
        </link>
      </model>
      <model name='Painel Solar_12'>
        <pose frame=''>8.56858 -15.5025 0 0 -0 0</pose>
        <scale>1 1 1</scale>
        <link name='link'>
          <pose frame=''>8.56858 -15.5025 0 0 -0 0</pose>
          <velocity>0 0 0 0 -0 0</velocity>
          <acceleration>0 0 0 0 -0 0</acceleration>
          <wrench>0 0 0 0 -0 0</wrench>
        </link>
      </model>
      <model name='Painel Solar_2'>
        <pose frame=''>2.06836 -4.29434 0 0 -0 0</pose>
        <scale>1 1 1</scale>
        <link name='link'>
          <pose frame=''>2.06836 -4.29434 0 0 -0 0</pose>
          <velocity>0 0 0 0 -0 0</velocity>
          <acceleration>0 0 0 0 -0 0</acceleration>
          <wrench>0 0 0 0 -0 0</wrench>
        </link>
      </model>
      <model name='Painel Solar_3'>
        <pose frame=''>8.58987 -4.3117 0 0 -0 0</pose>
        <scale>1 1 1</scale>
        <link name='link'>
          <pose frame=''>8.58987 -4.3117 0 0 -0 0</pose>
          <velocity>0 0 0 0 -0 0</velocity>
          <acceleration>0 0 0 0 -0 0</acceleration>
          <wrench>0 0 0 0 -0 0</wrench>
        </link>
      </model>
      <model name='Painel Solar_4'>
        <pose frame=''>-4.37608 -8.16933 0 0 -0 0</pose>
        <scale>1 1 1</scale>
        <link name='link'>
          <pose frame=''>-4.37608 -8.16933 0 0 -0 0</pose>
          <velocity>0 0 0 0 -0 0</velocity>
          <acceleration>0 0 0 0 -0 0</acceleration>
          <wrench>0 0 0 0 -0 0</wrench>
        </link>
      </model>
      <model name='Painel Solar_5'>
        <pose frame=''>2.06823 -8.23086 0 0 -0 0</pose>
        <scale>1 1 1</scale>
        <link name='link'>
          <pose frame=''>2.06823 -8.23086 0 0 -0 0</pose>
          <velocity>0 0 0 0 -0 0</velocity>
          <acceleration>0 0 0 0 -0 0</acceleration>
          <wrench>0 0 0 0 -0 0</wrench>
        </link>
      </model>
      <model name='Painel Solar_6'>
        <pose frame=''>8.55502 -8.22212 0 0 -0 0</pose>
        <scale>1 1 1</scale>
        <link name='link'>
          <pose frame=''>8.55502 -8.22212 0 0 -0 0</pose>
          <velocity>0 0 0 0 -0 0</velocity>
          <acceleration>0 0 0 0 -0 0</acceleration>
          <wrench>0 0 0 0 -0 0</wrench>
        </link>
      </model>
      <model name='Painel Solar_7'>
        <pose frame=''>-4.30602 -11.9474 0 0 -0 0</pose>
        <scale>1 1 1</scale>
        <link name='link'>
          <pose frame=''>-4.30602 -11.9474 0 0 -0 0</pose>
          <velocity>0 0 0 0 -0 0</velocity>
          <acceleration>0 0 0 0 -0 0</acceleration>
          <wrench>0 0 0 0 -0 0</wrench>
        </link>
      </model>
      <model name='Painel Solar_8'>
        <pose frame=''>2.19703 -12.0249 0 0 -0 0</pose>
        <scale>1 1 1</scale>
        <link name='link'>
          <pose frame=''>2.19703 -12.0249 0 0 -0 0</pose>
          <velocity>0 0 0 0 -0 0</velocity>
          <acceleration>0 0 0 0 -0 0</acceleration>
          <wrench>0 0 0 0 -0 0</wrench>
        </link>
      </model>
      <model name='Painel Solar_9'>
        <pose frame=''>8.53753 -12.0539 0 0 -0 0</pose>
        <scale>1 1 1</scale>
        <link name='link'>
          <pose frame=''>8.53753 -12.0539 0 0 -0 0</pose>
          <velocity>0 0 0 0 -0 0</velocity>
          <acceleration>0 0 0 0 -0 0</acceleration>
          <wrench>0 0 0 0 -0 0</wrench>
        </link>
      </model>
      <model name='gramado'>
        <pose frame=''>8.88656 -7.03656 0 0 -0 0</pose>
        <scale>1 1 1</scale>
        <link name='link'>
          <pose frame=''>8.88656 -7.03656 0 0 -0 0</pose>
          <velocity>0 0 0 0 -0 0</velocity>
          <acceleration>0 0 0 0 -0 0</acceleration>
          <wrench>0 0 0 0 -0 0</wrench>
        </link>
      </model>
      <model name='typhoon_h480'>
        <pose frame=''>1.0111 0.978202 0.269051 -2e-05 0.006259 0.012395</pose>
        <scale>1 1 1</scale>
        <link name='base_link'>
          <pose frame=''>1.0111 0.978202 0.269051 -2e-05 0.006259 0.012395</pose>
          <velocity>-1.8e-05 -5.7e-05 -0.000997 0.000499 -0.0002 -4.6e-05</velocity>
          <acceleration>-0.003939 0.011457 0.067985 -0.054514 -0.005144 0.021204</acceleration>
          <wrench>-0.007957 0.023143 0.137331 0 -0 0</wrench>
        </link>
        <link name='cgo3_camera_link'>
          <pose frame=''>1.00771 0.978158 0.269232 -5e-06 -0.014676 0.012391</pose>
          <velocity>0.000229 -5e-06 -0.00125 0.00035 0.001458 0.000231</velocity>
          <acceleration>-0.002123 0.000712 0.071989 0.012588 -0.434503 -0.020403</acceleration>
          <wrench>-0.000212 7.1e-05 0.007199 0 -0 0</wrench>
        </link>
        <link name='cgo3_horizontal_arm_link'>
          <pose frame=''>1.01111 0.9782 0.269037 -5e-06 0.006275 0.012391</pose>
          <velocity>-9e-06 -7e-06 -0.001231 0.000367 2.4e-05 0.000231</velocity>
          <acceleration>-0.00345 5.8e-05 0.084298 0.007442 -0.019135 -0.020408</acceleration>
          <wrench>-0.000345 6e-06 0.00843 0 -0 0</wrench>
        </link>
        <link name='cgo3_mount_link'>
          <pose frame=''>1.0111 0.978202 0.269044 -2e-05 0.006266 0.012395</pose>
          <velocity>-2.1e-05 -4.9e-05 -0.001113 0.000499 -0.000121 -0.000354</velocity>
          <acceleration>-0.002642 0.004512 0.076144 -0.056026 -0.008779 -0.135595</acceleration>
          <wrench>-0.000264 0.000451 0.007614 0 -0 0</wrench>
        </link>
        <link name='cgo3_vertical_arm_link'>
          <pose frame=''>1.01111 0.978202 0.26904 -2e-05 0.006272 0.012391</pose>
          <velocity>-2e-05 -3.1e-05 -0.001182 0.000502 -4.5e-05 0.00023</velocity>
          <acceleration>-0.001844 0.001432 0.080897 -0.055216 -0.01487 -0.019682</acceleration>
          <wrench>-0.000184 0.000143 0.00809 0 -0 0</wrench>
        </link>
        <link name='gps::link'>
          <pose frame=''>1.0111 0.978202 0.26905 -2e-05 0.006259 0.012395</pose>
          <velocity>-1.8e-05 -5.8e-05 -0.001024 0.000501 -0.000201 -4.7e-05</velocity>
          <acceleration>-0.004027 0.012106 0.069905 -0.055138 -0.002316 0.019162</acceleration>
          <wrench>-6e-05 0.000182 0.001049 0 -0 0</wrench>
        </link>
        <link name='left_leg'>
          <pose frame=''>1.01109 0.978205 0.269092 7.1e-05 0.006243 0.012394</pose>
          <velocity>-1.5e-05 0.000905 -0.000613 -0.00429 -6.6e-05 1e-05</velocity>
          <acceleration>3.3e-05 -0.002783 -4.6e-05 0.24044 0.002798 -0.000599</acceleration>
          <wrench>3e-06 -0.000278 -5e-06 0 -0 0</wrench>
        </link>
        <link name='right_leg'>
          <pose frame=''>1.01109 0.978201 0.269088 -5.8e-05 0.006233 0.012396</pose>
          <velocity>9e-06 -0.000908 -0.000609 0.004256 4.6e-05 -1.1e-05</velocity>
          <acceleration>-9.1e-05 0.003496 0.000128 -0.276536 -0.007124 0.001618</acceleration>
          <wrench>-9e-06 0.00035 1.3e-05 0 -0 0</wrench>
        </link>
        <link name='rotor_0'>
          <pose frame=''>0.800721 1.09837 0.352575 0.005475 -0.003111 2.10303</pose>
          <velocity>-2.9e-05 -9e-05 -0.001006 0.000503 0.000109 -0.000114</velocity>
          <acceleration>-0.00639 0.012329 0.054179 0.260428 0.071963 -3.0838</acceleration>
          <wrench>-3.2e-05 6.2e-05 0.000271 0 -0 0</wrench>
        </link>
        <link name='rotor_1'>
          <pose frame=''>1.22448 0.861077 0.349946 -0.005361 -0.003143 -2.08541</pose>
          <velocity>-4e-05 -0.000109 -0.00104 0.000507 -0.000484 -0.000114</velocity>
          <acceleration>-0.002097 0.019908 0.067919 0.638386 -0.095662 -3.08387</acceleration>
          <wrench>-1e-05 0.0001 0.00034 0 -0 0</wrench>
        </link>
        <link name='rotor_2'>
          <pose frame=''>0.803764 0.852862 0.35258 0.005475 -0.003111 2.10303</pose>
          <velocity>-4.1e-05 -9e-05 -0.001129 0.000503 0.00011 -0.000114</velocity>
          <acceleration>-0.001908 0.012485 0.067326 0.251801 0.057249 -3.08375</acceleration>
          <wrench>-1e-05 6.2e-05 0.000337 0 -0 0</wrench>
        </link>
        <link name='rotor_3'>
          <pose frame=''>1.22151 1.10058 0.349941 -4.2e-05 0.006259 0.008798</pose>
          <velocity>-2.8e-05 -0.000109 -0.00092 0.000502 -0.000201 -0.000114</velocity>
          <acceleration>-0.006467 0.019892 0.055222 -0.063004 -0.003236 0.002001</acceleration>
          <wrench>-3.2e-05 9.9e-05 0.000276 0 -0 0</wrench>
        </link>
        <link name='rotor_4'>
          <pose frame=''>1.00673 1.22087 0.351272 -4.2e-05 0.006259 0.008815</pose>
          <velocity>-2.3e-05 -0.0001 -0.000902 0.000505 -0.000201 -0.000114</velocity>
          <acceleration>-0.008617 0.015941 0.048421 -0.062267 -0.003213 0.001999</acceleration>
          <wrench>-4.3e-05 8e-05 0.000242 0 -0 0</wrench>
        </link>
        <link name='rotor_5'>
          <pose frame=''>1.01275 0.7355 0.351281 -0.005361 -0.003143 -2.08541</pose>
          <velocity>-4.6e-05 -9.9e-05 -0.001146 0.000506 -0.000486 -0.000114</velocity>
          <acceleration>0.000192 0.016202 0.074016 0.567882 0.029446 -3.08342</acceleration>
          <wrench>1e-06 8.1e-05 0.00037 0 -0 0</wrench>
        </link>
        <link name='sonar::link'>
          <pose frame=''>1.09091 0.97919 0.238549 2e-05 -0.006259 -3.1292</pose>
          <velocity>-1.2e-05 -4.6e-05 -0.001007 0.000502 -0.000201 -3.1e-05</velocity>
          <acceleration>-0.003967 0.011928 0.070033 -0.055059 -0.002315 0.017067</acceleration>
          <wrench>0 0 0 0 -0 0</wrench>
        </link>
        <link name='typhoon_h480/imu_link'>
          <pose frame=''>1.0111 0.978202 0.26905 -2e-05 0.006259 0.012395</pose>
          <velocity>-1.8e-05 -5.8e-05 -0.001024 0.000503 -0.000201 -4.8e-05</velocity>
          <acceleration>-0.004021 0.012087 0.069947 -0.055451 -0.002338 0.019217</acceleration>
          <wrench>-6e-05 0.000181 0.001049 0 -0 0</wrench>
        </link>
      </model>
      <model name='world_ned'>
        <pose frame=''>0 0 0 0 -0 0</pose>
        <scale>1 1 1</scale>
        <link name='world_ned'>
          <pose frame=''>0 0 0 -3.14159 -0 1.5708</pose>
          <velocity>0 0 0 0 -0 0</velocity>
          <acceleration>0 0 0 0 -0 0</acceleration>
          <wrench>0 0 0 0 -0 0</wrench>
        </link>
      </model>
      <light name='sun'>
        <pose frame=''>0 0 10 0 -0 0</pose>
      </light>
      <light name='sun1'>
        <pose frame=''>50 0 150 0 -0 0</pose>
      </light>
      <light name='sun2'>
        <pose frame=''>0 50 0 0 -0 0</pose>
      </light>
      <light name='sun3'>
        <pose frame=''>0 -50 0 0 -0 0</pose>
      </light>
      <light name='sun_diffuse'>
        <pose frame=''>-50 0 -150 0 -0 0</pose>
      </light>
    </state>
  </world>
</sdf>
